Workbook

Sheet Read Me
A1: Solo Consultant CFO Tracker
A2: Companion workbook to outputs/cfo-survival-workflow.md
A4: How to use this file
A5: Blue text | B5: A cell you type into. Everything else is a formula — do not overwrite it.
A6: Yellow fill | B6: A key assumption. Update these monthly during your board package review.
A7: Green text | B7: A value pulled in from another sheet.
A9: Sheet order
A10: 1. Assumptions | B10: Set once, review monthly. Drives your Minimum Viable Retainer Run-Rate (MVRR) and hourly-rate threshold.
A11: 2. Daily Vital Signs | B11: Log bank balance + AR + today's billing/collections once a day. Takes under 5 minutes.
A12: 3. Weekly - Earned vs Invoiced | B12: Friday Block 1. One row per active advisory project.
A13: 4. Weekly - Scope Creep | B13: Friday Block 2. One row per active advisory project.
A14: 5. Weekly - Retainer Risk | B14: Friday Block 3. One row per retainer. Feeds the 13-Week Forecast.
A15: 6. Monthly - Breakeven | B15: First Monday of the month. Tells you the exact revenue you need to survive.
A16: 7. Project Profitability | B16: First Monday of the month. True Effective Hourly Rate (TEHR) per engagement.
A17: 8. 13-Week Pipeline | B17: List every open deal and retainer renewal with a probability weight.
A18: 9. 13-Week Forecast | B18: Rolls the pipeline into a week-by-week cash forecast: Floor / Base / Best Case.
A20: Rule | B20: Every red flag in this workbook has a same-week action attached in the workflow doc. A number you check but don't act on is just anxiety with extra steps.

Sheet Assumptions
A1: Assumptions — Update Monthly
A3: Input | B3: Value | C3: Notes
A4: Fixed Monthly Overhead ($) | B4: 3500 | C4: Software, insurance, coworking, retained subcontractors, accounting fees — paid whether or not you close a deal.
A5: Minimum Personal Draw ($/month) | B5: 6000 | C5: Your survival number, not your ideal salary.
A6: Monthly Debt Service ($) | B6: 500 | C6: Loan / credit line payments.
A7: Variable Cost % of Revenue | B7: 0.08 | C7: Payment processing, referral fees, per-project subcontractor delivery cost as a % of revenue.
A8: Realistic Monthly Billable Hours | B8: 80 | C8: Hours you can actually deliver in a month, after admin and sales time.
A10: Calculated — Formula A: Minimum Viable Retainer Run-Rate (MVRR)
A11: MVRR = (Overhead + Draw + Debt) ÷ (1 − Variable Cost %) | B11: =(B4+B5+B6)/(1-B7) -> 10869.565
A13: Calculated — Minimum Viable Hourly Rate & TEHR Threshold
A14: Minimum Viable Hourly Rate = MVRR ÷ Realistic Monthly Billable Hours | B14: =B11/B8 -> 135.86957
A15: TEHR Red-Flag Threshold (1.5x Minimum Viable Hourly Rate) | B15: =B14*1.5 -> 203.80435 | C15: Any project with True Effective Hourly Rate below this is a pricing problem — see sheet 7.

Sheet 2. Daily Vital Signs
A1: Daily 5-Minute Vital Sign Check
A2: Log this every morning before client work. Under 5 minutes.
A4: Date | B4: Bank Balance | C4: Cash Change | D4: Trailing 30-Day Avg Daily Burn | E4: Cash Runway (Days) | F4: AR 0-30 | G4: AR 31-60 | H4: AR 61+ | I4: Total AR | J4: Billed Today | K4: Collected Today | L4: Revenue Realization %
A5: 46265 | B5: 42000 | D5: =IFERROR(-AVERAGE(C5:C5),"-") -> - | E5: =IF(OR(B5="",D5="-",D5<=0),"-",B5/D5) -> - | F5: 1200 | G5: 400 | H5: 0 | I5: =SUM(F5:H5) -> 1600 | J5: 1500 | K5: 1100 | L5: =IFERROR(K5/J5,"-") -> 0.73333333
A6: =A5+1 -> 46266 | C6: =IF(OR(B6="",B5=""),"",B6-B5) | D6: =IFERROR(-AVERAGE(C5:C6),"-") -> - | E6: =IF(OR(B6="",D6="-",D6<=0),"-",B6/D6) -> - | I6: =SUM(F6:H6) -> 0 | L6: =IFERROR(K6/J6,"-") -> -
A7: =A6+1 -> 46267 | C7: =IF(OR(B7="",B6=""),"",B7-B6) | D7: =IFERROR(-AVERAGE(C5:C7),"-") -> - | E7: =IF(OR(B7="",D7="-",D7<=0),"-",B7/D7) -> - | I7: =SUM(F7:H7) -> 0 | L7: =IFERROR(K7/J7,"-") -> -
A8: =A7+1 -> 46268 | C8: =IF(OR(B8="",B7=""),"",B8-B7) | D8: =IFERROR(-AVERAGE(C5:C8),"-") -> - | E8: =IF(OR(B8="",D8="-",D8<=0),"-",B8/D8) -> - | I8: =SUM(F8:H8) -> 0 | L8: =IFERROR(K8/J8,"-") -> -
A9: =A8+1 -> 46269 | C9: =IF(OR(B9="",B8=""),"",B9-B8) | D9: =IFERROR(-AVERAGE(C5:C9),"-") -> - | E9: =IF(OR(B9="",D9="-",D9<=0),"-",B9/D9) -> - | I9: =SUM(F9:H9) -> 0 | L9: =IFERROR(K9/J9,"-") -> -
A10: =A9+1 -> 46270 | C10: =IF(OR(B10="",B9=""),"",B10-B9) | D10: =IFERROR(-AVERAGE(C5:C10),"-") -> - | E10: =IF(OR(B10="",D10="-",D10<=0),"-",B10/D10) -> - | I10: =SUM(F10:H10) -> 0 | L10: =IFERROR(K10/J10,"-") -> -
A11: =A10+1 -> 46271 | C11: =IF(OR(B11="",B10=""),"",B11-B10) | D11: =IFERROR(-AVERAGE(C5:C11),"-") -> - | E11: =IF(OR(B11="",D11="-",D11<=0),"-",B11/D11) -> - | I11: =SUM(F11:H11) -> 0 | L11: =IFERROR(K11/J11,"-") -> -
A12: =A11+1 -> 46272 | C12: =IF(OR(B12="",B11=""),"",B12-B11) | D12: =IFERROR(-AVERAGE(C5:C12),"-") -> - | E12: =IF(OR(B12="",D12="-",D12<=0),"-",B12/D12) -> - | I12: =SUM(F12:H12) -> 0 | L12: =IFERROR(K12/J12,"-") -> -
A13: =A12+1 -> 46273 | C13: =IF(OR(B13="",B12=""),"",B13-B12) | D13: =IFERROR(-AVERAGE(C5:C13),"-") -> - | E13: =IF(OR(B13="",D13="-",D13<=0),"-",B13/D13) -> - | I13: =SUM(F13:H13) -> 0 | L13: =IFERROR(K13/J13,"-") -> -
A14: =A13+1 -> 46274 | C14: =IF(OR(B14="",B13=""),"",B14-B13) | D14: =IFERROR(-AVERAGE(C5:C14),"-") -> - | E14: =IF(OR(B14="",D14="-",D14<=0),"-",B14/D14) -> - | I14: =SUM(F14:H14) -> 0 | L14: =IFERROR(K14/J14,"-") -> -
A15: =A14+1 -> 46275 | C15: =IF(OR(B15="",B14=""),"",B15-B14) | D15: =IFERROR(-AVERAGE(C5:C15),"-") -> - | E15: =IF(OR(B15="",D15="-",D15<=0),"-",B15/D15) -> - | I15: =SUM(F15:H15) -> 0 | L15: =IFERROR(K15/J15,"-") -> -
A16: =A15+1 -> 46276 | C16: =IF(OR(B16="",B15=""),"",B16-B15) | D16: =IFERROR(-AVERAGE(C5:C16),"-") -> - | E16: =IF(OR(B16="",D16="-",D16<=0),"-",B16/D16) -> - | I16: =SUM(F16:H16) -> 0 | L16: =IFERROR(K16/J16,"-") -> -
A17: =A16+1 -> 46277 | C17: =IF(OR(B17="",B16=""),"",B17-B16) | D17: =IFERROR(-AVERAGE(C5:C17),"-") -> - | E17: =IF(OR(B17="",D17="-",D17<=0),"-",B17/D17) -> - | I17: =SUM(F17:H17) -> 0 | L17: =IFERROR(K17/J17,"-") -> -
A18: =A17+1 -> 46278 | C18: =IF(OR(B18="",B17=""),"",B18-B17) | D18: =IFERROR(-AVERAGE(C5:C18),"-") -> - | E18: =IF(OR(B18="",D18="-",D18<=0),"-",B18/D18) -> - | I18: =SUM(F18:H18) -> 0 | L18: =IFERROR(K18/J18,"-") -> -
A19: =A18+1 -> 46279 | C19: =IF(OR(B19="",B18=""),"",B19-B18) | D19: =IFERROR(-AVERAGE(C5:C19),"-") -> - | E19: =IF(OR(B19="",D19="-",D19<=0),"-",B19/D19) -> - | I19: =SUM(F19:H19) -> 0 | L19: =IFERROR(K19/J19,"-") -> -
A20: =A19+1 -> 46280 | C20: =IF(OR(B20="",B19=""),"",B20-B19) | D20: =IFERROR(-AVERAGE(C5:C20),"-") -> - | E20: =IF(OR(B20="",D20="-",D20<=0),"-",B20/D20) -> - | I20: =SUM(F20:H20) -> 0 | L20: =IFERROR(K20/J20,"-") -> -
A21: =A20+1 -> 46281 | C21: =IF(OR(B21="",B20=""),"",B21-B20) | D21: =IFERROR(-AVERAGE(C5:C21),"-") -> - | E21: =IF(OR(B21="",D21="-",D21<=0),"-",B21/D21) -> - | I21: =SUM(F21:H21) -> 0 | L21: =IFERROR(K21/J21,"-") -> -
A22: =A21+1 -> 46282 | C22: =IF(OR(B22="",B21=""),"",B22-B21) | D22: =IFERROR(-AVERAGE(C5:C22),"-") -> - | E22: =IF(OR(B22="",D22="-",D22<=0),"-",B22/D22) -> - | I22: =SUM(F22:H22) -> 0 | L22: =IFERROR(K22/J22,"-") -> -
A23: =A22+1 -> 46283 | C23: =IF(OR(B23="",B22=""),"",B23-B22) | D23: =IFERROR(-AVERAGE(C5:C23),"-") -> - | E23: =IF(OR(B23="",D23="-",D23<=0),"-",B23/D23) -> - | I23: =SUM(F23:H23) -> 0 | L23: =IFERROR(K23/J23,"-") -> -
A24: =A23+1 -> 46284 | C24: =IF(OR(B24="",B23=""),"",B24-B23) | D24: =IFERROR(-AVERAGE(C5:C24),"-") -> - | E24: =IF(OR(B24="",D24="-",D24<=0),"-",B24/D24) -> - | I24: =SUM(F24:H24) -> 0 | L24: =IFERROR(K24/J24,"-") -> -
A25: =A24+1 -> 46285 | C25: =IF(OR(B25="",B24=""),"",B25-B24) | D25: =IFERROR(-AVERAGE(C5:C25),"-") -> - | E25: =IF(OR(B25="",D25="-",D25<=0),"-",B25/D25) -> - | I25: =SUM(F25:H25) -> 0 | L25: =IFERROR(K25/J25,"-") -> -
A26: =A25+1 -> 46286 | C26: =IF(OR(B26="",B25=""),"",B26-B25) | D26: =IFERROR(-AVERAGE(C5:C26),"-") -> - | E26: =IF(OR(B26="",D26="-",D26<=0),"-",B26/D26) -> - | I26: =SUM(F26:H26) -> 0 | L26: =IFERROR(K26/J26,"-") -> -
A27: =A26+1 -> 46287 | C27: =IF(OR(B27="",B26=""),"",B27-B26) | D27: =IFERROR(-AVERAGE(C5:C27),"-") -> - | E27: =IF(OR(B27="",D27="-",D27<=0),"-",B27/D27) -> - | I27: =SUM(F27:H27) -> 0 | L27: =IFERROR(K27/J27,"-") -> -
A28: =A27+1 -> 46288 | C28: =IF(OR(B28="",B27=""),"",B28-B27) | D28: =IFERROR(-AVERAGE(C5:C28),"-") -> - | E28: =IF(OR(B28="",D28="-",D28<=0),"-",B28/D28) -> - | I28: =SUM(F28:H28) -> 0 | L28: =IFERROR(K28/J28,"-") -> -
A29: =A28+1 -> 46289 | C29: =IF(OR(B29="",B28=""),"",B29-B28) | D29: =IFERROR(-AVERAGE(C5:C29),"-") -> - | E29: =IF(OR(B29="",D29="-",D29<=0),"-",B29/D29) -> - | I29: =SUM(F29:H29) -> 0 | L29: =IFERROR(K29/J29,"-") -> -
A30: =A29+1 -> 46290 | C30: =IF(OR(B30="",B29=""),"",B30-B29) | D30: =IFERROR(-AVERAGE(C5:C30),"-") -> - | E30: =IF(OR(B30="",D30="-",D30<=0),"-",B30/D30) -> - | I30: =SUM(F30:H30) -> 0 | L30: =IFERROR(K30/J30,"-") -> -
A31: =A30+1 -> 46291 | C31: =IF(OR(B31="",B30=""),"",B31-B30) | D31: =IFERROR(-AVERAGE(C5:C31),"-") -> - | E31: =IF(OR(B31="",D31="-",D31<=0),"-",B31/D31) -> - | I31: =SUM(F31:H31) -> 0 | L31: =IFERROR(K31/J31,"-") -> -
A32: =A31+1 -> 46292 | C32: =IF(OR(B32="",B31=""),"",B32-B31) | D32: =IFERROR(-AVERAGE(C5:C32),"-") -> - | E32: =IF(OR(B32="",D32="-",D32<=0),"-",B32/D32) -> - | I32: =SUM(F32:H32) -> 0 | L32: =IFERROR(K32/J32,"-") -> -
A33: =A32+1 -> 46293 | C33: =IF(OR(B33="",B32=""),"",B33-B32) | D33: =IFERROR(-AVERAGE(C5:C33),"-") -> - | E33: =IF(OR(B33="",D33="-",D33<=0),"-",B33/D33) -> - | I33: =SUM(F33:H33) -> 0 | L33: =IFERROR(K33/J33,"-") -> -
A34: =A33+1 -> 46294 | C34: =IF(OR(B34="",B33=""),"",B34-B33) | D34: =IFERROR(-AVERAGE(C5:C34),"-") -> - | E34: =IF(OR(B34="",D34="-",D34<=0),"-",B34/D34) -> - | I34: =SUM(F34:H34) -> 0 | L34: =IFERROR(K34/J34,"-") -> -
A35: =A34+1 -> 46295 | C35: =IF(OR(B35="",B34=""),"",B35-B34) | D35: =IFERROR(-AVERAGE(C6:C35),"-") -> - | E35: =IF(OR(B35="",D35="-",D35<=0),"-",B35/D35) -> - | I35: =SUM(F35:H35) -> 0 | L35: =IFERROR(K35/J35,"-") -> -
A36: =A35+1 -> 46296 | C36: =IF(OR(B36="",B35=""),"",B36-B35) | D36: =IFERROR(-AVERAGE(C7:C36),"-") -> - | E36: =IF(OR(B36="",D36="-",D36<=0),"-",B36/D36) -> - | I36: =SUM(F36:H36) -> 0 | L36: =IFERROR(K36/J36,"-") -> -
A37: =A36+1 -> 46297 | C37: =IF(OR(B37="",B36=""),"",B37-B36) | D37: =IFERROR(-AVERAGE(C8:C37),"-") -> - | E37: =IF(OR(B37="",D37="-",D37<=0),"-",B37/D37) -> - | I37: =SUM(F37:H37) -> 0 | L37: =IFERROR(K37/J37,"-") -> -
A38: =A37+1 -> 46298 | C38: =IF(OR(B38="",B37=""),"",B38-B37) | D38: =IFERROR(-AVERAGE(C9:C38),"-") -> - | E38: =IF(OR(B38="",D38="-",D38<=0),"-",B38/D38) -> - | I38: =SUM(F38:H38) -> 0 | L38: =IFERROR(K38/J38,"-") -> -
A39: =A38+1 -> 46299 | C39: =IF(OR(B39="",B38=""),"",B39-B38) | D39: =IFERROR(-AVERAGE(C10:C39),"-") -> - | E39: =IF(OR(B39="",D39="-",D39<=0),"-",B39/D39) -> - | I39: =SUM(F39:H39) -> 0 | L39: =IFERROR(K39/J39,"-") -> -
A40: =A39+1 -> 46300 | C40: =IF(OR(B40="",B39=""),"",B40-B39) | D40: =IFERROR(-AVERAGE(C11:C40),"-") -> - | E40: =IF(OR(B40="",D40="-",D40<=0),"-",B40/D40) -> - | I40: =SUM(F40:H40) -> 0 | L40: =IFERROR(K40/J40,"-") -> -
A41: =A40+1 -> 46301 | C41: =IF(OR(B41="",B40=""),"",B41-B40) | D41: =IFERROR(-AVERAGE(C12:C41),"-") -> - | E41: =IF(OR(B41="",D41="-",D41<=0),"-",B41/D41) -> - | I41: =SUM(F41:H41) -> 0 | L41: =IFERROR(K41/J41,"-") -> -
...

Sheet 3. Weekly - Earned vs Invoiced
A1: Friday Block 1 — Earned vs. Invoiced Revenue
A2: One row per active advisory project. Update every Friday.
A4: Project | B4: Contract Value | C4: Total Scoped Hours | D4: Hours Delivered to Date | E4: % Complete | F4: Earned Revenue | G4: Invoiced Revenue | H4: Gap (Earned − Invoiced) | I4: Flag
A5: Acme Corp — Strategy Advisory | B5: 60000 | C5: 300 | D5: 165 | E5: =IFERROR(D5/C5,"-") -> 0.55 | F5: =IFERROR(B5*E5,"-") -> 33000 | G5: 48000 | H5: =IFERROR(F5-G5,"-") -> -15000 | I5: =IF(A5="","",IF(H5="-","-",IF(H5>0,"INVOICE NOW",IF(H5<-0.2*B5,"Ahead - Monitor","OK")))) -> Ahead - Monitor
E6: =IFERROR(D6/C6,"-") -> - | F6: =IFERROR(B6*E6,"-") -> - | H6: =IFERROR(F6-G6,"-") -> - | I6: =IF(A6="","",IF(H6="-","-",IF(H6>0,"INVOICE NOW",IF(H6<-0.2*B6,"Ahead - Monitor","OK"))))
E7: =IFERROR(D7/C7,"-") -> - | F7: =IFERROR(B7*E7,"-") -> - | H7: =IFERROR(F7-G7,"-") -> - | I7: =IF(A7="","",IF(H7="-","-",IF(H7>0,"INVOICE NOW",IF(H7<-0.2*B7,"Ahead - Monitor","OK"))))
E8: =IFERROR(D8/C8,"-") -> - | F8: =IFERROR(B8*E8,"-") -> - | H8: =IFERROR(F8-G8,"-") -> - | I8: =IF(A8="","",IF(H8="-","-",IF(H8>0,"INVOICE NOW",IF(H8<-0.2*B8,"Ahead - Monitor","OK"))))
E9: =IFERROR(D9/C9,"-") -> - | F9: =IFERROR(B9*E9,"-") -> - | H9: =IFERROR(F9-G9,"-") -> - | I9: =IF(A9="","",IF(H9="-","-",IF(H9>0,"INVOICE NOW",IF(H9<-0.2*B9,"Ahead - Monitor","OK"))))
E10: =IFERROR(D10/C10,"-") -> - | F10: =IFERROR(B10*E10,"-") -> - | H10: =IFERROR(F10-G10,"-") -> - | I10: =IF(A10="","",IF(H10="-","-",IF(H10>0,"INVOICE NOW",IF(H10<-0.2*B10,"Ahead - Monitor","OK"))))
E11: =IFERROR(D11/C11,"-") -> - | F11: =IFERROR(B11*E11,"-") -> - | H11: =IFERROR(F11-G11,"-") -> - | I11: =IF(A11="","",IF(H11="-","-",IF(H11>0,"INVOICE NOW",IF(H11<-0.2*B11,"Ahead - Monitor","OK"))))
E12: =IFERROR(D12/C12,"-") -> - | F12: =IFERROR(B12*E12,"-") -> - | H12: =IFERROR(F12-G12,"-") -> - | I12: =IF(A12="","",IF(H12="-","-",IF(H12>0,"INVOICE NOW",IF(H12<-0.2*B12,"Ahead - Monitor","OK"))))
E13: =IFERROR(D13/C13,"-") -> - | F13: =IFERROR(B13*E13,"-") -> - | H13: =IFERROR(F13-G13,"-") -> - | I13: =IF(A13="","",IF(H13="-","-",IF(H13>0,"INVOICE NOW",IF(H13<-0.2*B13,"Ahead - Monitor","OK"))))
E14: =IFERROR(D14/C14,"-") -> - | F14: =IFERROR(B14*E14,"-") -> - | H14: =IFERROR(F14-G14,"-") -> - | I14: =IF(A14="","",IF(H14="-","-",IF(H14>0,"INVOICE NOW",IF(H14<-0.2*B14,"Ahead - Monitor","OK"))))
E15: =IFERROR(D15/C15,"-") -> - | F15: =IFERROR(B15*E15,"-") -> - | H15: =IFERROR(F15-G15,"-") -> - | I15: =IF(A15="","",IF(H15="-","-",IF(H15>0,"INVOICE NOW",IF(H15<-0.2*B15,"Ahead - Monitor","OK"))))
E16: =IFERROR(D16/C16,"-") -> - | F16: =IFERROR(B16*E16,"-") -> - | H16: =IFERROR(F16-G16,"-") -> - | I16: =IF(A16="","",IF(H16="-","-",IF(H16>0,"INVOICE NOW",IF(H16<-0.2*B16,"Ahead - Monitor","OK"))))

Sheet 4. Weekly - Scope Creep
A1: Friday Block 2 — Scope Creep Audit
A2: One row per active advisory project. Timeline elapsed, not % complete — catches drift early.
A4: Project | B4: Total Budgeted Hours | C4: Timeline Elapsed % | D4: Budgeted Hours to Date | E4: Actual Hours Logged | F4: Variance % | G4: Flag
A5: Acme Corp — Strategy Advisory | B5: 300 | C5: 0.55 | D5: =IFERROR(B5*C5,"-") -> 165 | E5: 185 | F5: =IFERROR((E5-D5)/D5,"-") -> 0.12121212 | G5: =IF(A5="","",IF(F5="-","-",IF(F5>0.3,"CHANGE ORDER NOW",IF(F5>0.15,"Send Scope Check","OK")))) -> OK
D6: =IFERROR(B6*C6,"-") -> 0 | F6: =IFERROR((E6-D6)/D6,"-") -> - | G6: =IF(A6="","",IF(F6="-","-",IF(F6>0.3,"CHANGE ORDER NOW",IF(F6>0.15,"Send Scope Check","OK"))))
D7: =IFERROR(B7*C7,"-") -> 0 | F7: =IFERROR((E7-D7)/D7,"-") -> - | G7: =IF(A7="","",IF(F7="-","-",IF(F7>0.3,"CHANGE ORDER NOW",IF(F7>0.15,"Send Scope Check","OK"))))
D8: =IFERROR(B8*C8,"-") -> 0 | F8: =IFERROR((E8-D8)/D8,"-") -> - | G8: =IF(A8="","",IF(F8="-","-",IF(F8>0.3,"CHANGE ORDER NOW",IF(F8>0.15,"Send Scope Check","OK"))))
D9: =IFERROR(B9*C9,"-") -> 0 | F9: =IFERROR((E9-D9)/D9,"-") -> - | G9: =IF(A9="","",IF(F9="-","-",IF(F9>0.3,"CHANGE ORDER NOW",IF(F9>0.15,"Send Scope Check","OK"))))
D10: =IFERROR(B10*C10,"-") -> 0 | F10: =IFERROR((E10-D10)/D10,"-") -> - | G10: =IF(A10="","",IF(F10="-","-",IF(F10>0.3,"CHANGE ORDER NOW",IF(F10>0.15,"Send Scope Check","OK"))))
D11: =IFERROR(B11*C11,"-") -> 0 | F11: =IFERROR((E11-D11)/D11,"-") -> - | G11: =IF(A11="","",IF(F11="-","-",IF(F11>0.3,"CHANGE ORDER NOW",IF(F11>0.15,"Send Scope Check","OK"))))
D12: =IFERROR(B12*C12,"-") -> 0 | F12: =IFERROR((E12-D12)/D12,"-") -> - | G12: =IF(A12="","",IF(F12="-","-",IF(F12>0.3,"CHANGE ORDER NOW",IF(F12>0.15,"Send Scope Check","OK"))))
D13: =IFERROR(B13*C13,"-") -> 0 | F13: =IFERROR((E13-D13)/D13,"-") -> - | G13: =IF(A13="","",IF(F13="-","-",IF(F13>0.3,"CHANGE ORDER NOW",IF(F13>0.15,"Send Scope Check","OK"))))
D14: =IFERROR(B14*C14,"-") -> 0 | F14: =IFERROR((E14-D14)/D14,"-") -> - | G14: =IF(A14="","",IF(F14="-","-",IF(F14>0.3,"CHANGE ORDER NOW",IF(F14>0.15,"Send Scope Check","OK"))))
D15: =IFERROR(B15*C15,"-") -> 0 | F15: =IFERROR((E15-D15)/D15,"-") -> - | G15: =IF(A15="","",IF(F15="-","-",IF(F15>0.3,"CHANGE ORDER NOW",IF(F15>0.15,"Send Scope Check","OK"))))
D16: =IFERROR(B16*C16,"-") -> 0 | F16: =IFERROR((E16-D16)/D16,"-") -> - | G16: =IF(A16="","",IF(F16="-","-",IF(F16>0.3,"CHANGE ORDER NOW",IF(F16>0.15,"Send Scope Check","OK"))))

Sheet 5. Weekly - Retainer Risk
A1: Friday Block 3 — Retainer Renewal Risk
A2: Score each signal Green / Yellow / Red every Friday.
A4: Retainer | B4: Monthly Value | C4: Renewal Date | D4: Responsiveness | E4: Usage | F4: Renewal Conversation | G4: Risk Score | H4: Renewal Probability | I4: This Week's Action
A5: Beta Industries — Monthly Advisory | B5: 4000 | C5: 46290 | D5: Yellow | E5: Green | F5: Yellow | G5: =IF(A5="","",COUNTIF(D5:F5,"Yellow")+COUNTIF(D5:F5,"Red")) -> 2 | H5: =IF(A5="","",IF(OR(D5="Red",E5="Red"),0.15,IF(G5>=2,0.3,IF(G5=1,0.65,0.9)))) -> 0.3 | I5: =IF(A5="","",IF(G5>=2,"Send value-recap touchpoint this week","Monitor")) -> Send value-recap touchpoint this week
G6: =IF(A6="","",COUNTIF(D6:F6,"Yellow")+COUNTIF(D6:F6,"Red")) | H6: =IF(A6="","",IF(OR(D6="Red",E6="Red"),0.15,IF(G6>=2,0.3,IF(G6=1,0.65,0.9)))) | I6: =IF(A6="","",IF(G6>=2,"Send value-recap touchpoint this week","Monitor"))
G7: =IF(A7="","",COUNTIF(D7:F7,"Yellow")+COUNTIF(D7:F7,"Red")) | H7: =IF(A7="","",IF(OR(D7="Red",E7="Red"),0.15,IF(G7>=2,0.3,IF(G7=1,0.65,0.9)))) | I7: =IF(A7="","",IF(G7>=2,"Send value-recap touchpoint this week","Monitor"))
G8: =IF(A8="","",COUNTIF(D8:F8,"Yellow")+COUNTIF(D8:F8,"Red")) | H8: =IF(A8="","",IF(OR(D8="Red",E8="Red"),0.15,IF(G8>=2,0.3,IF(G8=1,0.65,0.9)))) | I8: =IF(A8="","",IF(G8>=2,"Send value-recap touchpoint this week","Monitor"))
G9: =IF(A9="","",COUNTIF(D9:F9,"Yellow")+COUNTIF(D9:F9,"Red")) | H9: =IF(A9="","",IF(OR(D9="Red",E9="Red"),0.15,IF(G9>=2,0.3,IF(G9=1,0.65,0.9)))) | I9: =IF(A9="","",IF(G9>=2,"Send value-recap touchpoint this week","Monitor"))
G10: =IF(A10="","",COUNTIF(D10:F10,"Yellow")+COUNTIF(D10:F10,"Red")) | H10: =IF(A10="","",IF(OR(D10="Red",E10="Red"),0.15,IF(G10>=2,0.3,IF(G10=1,0.65,0.9)))) | I10: =IF(A10="","",IF(G10>=2,"Send value-recap touchpoint this week","Monitor"))
G11: =IF(A11="","",COUNTIF(D11:F11,"Yellow")+COUNTIF(D11:F11,"Red")) | H11: =IF(A11="","",IF(OR(D11="Red",E11="Red"),0.15,IF(G11>=2,0.3,IF(G11=1,0.65,0.9)))) | I11: =IF(A11="","",IF(G11>=2,"Send value-recap touchpoint this week","Monitor"))
G12: =IF(A12="","",COUNTIF(D12:F12,"Yellow")+COUNTIF(D12:F12,"Red")) | H12: =IF(A12="","",IF(OR(D12="Red",E12="Red"),0.15,IF(G12>=2,0.3,IF(G12=1,0.65,0.9)))) | I12: =IF(A12="","",IF(G12>=2,"Send value-recap touchpoint this week","Monitor"))
G13: =IF(A13="","",COUNTIF(D13:F13,"Yellow")+COUNTIF(D13:F13,"Red")) | H13: =IF(A13="","",IF(OR(D13="Red",E13="Red"),0.15,IF(G13>=2,0.3,IF(G13=1,0.65,0.9)))) | I13: =IF(A13="","",IF(G13>=2,"Send value-recap touchpoint this week","Monitor"))
G14: =IF(A14="","",COUNTIF(D14:F14,"Yellow")+COUNTIF(D14:F14,"Red")) | H14: =IF(A14="","",IF(OR(D14="Red",E14="Red"),0.15,IF(G14>=2,0.3,IF(G14=1,0.65,0.9)))) | I14: =IF(A14="","",IF(G14>=2,"Send value-recap touchpoint this week","Monitor"))

Sheet 6. Monthly - Breakeven
A1: Monthly Board Slide 4 — Breakeven Analysis
A2: Run the first Monday of every month.
A4: Formula: Breakeven Revenue = Total Fixed Costs ÷ Contribution Margin %
A6: Month | B6: Total Fixed Costs | C6: Revenue | D6: Variable Costs | E6: Contribution Margin % | F6: Breakeven Revenue
A7: =EDATE(TODAY(),-11) -> 45930 | B7: =Assumptions!$B$4+Assumptions!$B$5+Assumptions!$B$6 -> 10000 | E7: =IFERROR((C7-D7)/C7,"-") -> - | F7: =IFERROR(B7/E7,"-") -> -
A8: =EDATE(TODAY(),-10) -> 45961 | B8: =Assumptions!$B$4+Assumptions!$B$5+Assumptions!$B$6 -> 10000 | E8: =IFERROR((C8-D8)/C8,"-") -> - | F8: =IFERROR(B8/E8,"-") -> -
A9: =EDATE(TODAY(),-9) -> 45991 | B9: =Assumptions!$B$4+Assumptions!$B$5+Assumptions!$B$6 -> 10000 | E9: =IFERROR((C9-D9)/C9,"-") -> - | F9: =IFERROR(B9/E9,"-") -> -
A10: =EDATE(TODAY(),-8) -> 46022 | B10: =Assumptions!$B$4+Assumptions!$B$5+Assumptions!$B$6 -> 10000 | E10: =IFERROR((C10-D10)/C10,"-") -> - | F10: =IFERROR(B10/E10,"-") -> -
A11: =EDATE(TODAY(),-7) -> 46053 | B11: =Assumptions!$B$4+Assumptions!$B$5+Assumptions!$B$6 -> 10000 | E11: =IFERROR((C11-D11)/C11,"-") -> - | F11: =IFERROR(B11/E11,"-") -> -
A12: =EDATE(TODAY(),-6) -> 46081 | B12: =Assumptions!$B$4+Assumptions!$B$5+Assumptions!$B$6 -> 10000 | E12: =IFERROR((C12-D12)/C12,"-") -> - | F12: =IFERROR(B12/E12,"-") -> -
A13: =EDATE(TODAY(),-5) -> 46112 | B13: =Assumptions!$B$4+Assumptions!$B$5+Assumptions!$B$6 -> 10000 | E13: =IFERROR((C13-D13)/C13,"-") -> - | F13: =IFERROR(B13/E13,"-") -> -
A14: =EDATE(TODAY(),-4) -> 46142 | B14: =Assumptions!$B$4+Assumptions!$B$5+Assumptions!$B$6 -> 10000 | E14: =IFERROR((C14-D14)/C14,"-") -> - | F14: =IFERROR(B14/E14,"-") -> -
A15: =EDATE(TODAY(),-3) -> 46173 | B15: =Assumptions!$B$4+Assumptions!$B$5+Assumptions!$B$6 -> 10000 | E15: =IFERROR((C15-D15)/C15,"-") -> - | F15: =IFERROR(B15/E15,"-") -> -
A16: =EDATE(TODAY(),-2) -> 46203 | B16: =Assumptions!$B$4+Assumptions!$B$5+Assumptions!$B$6 -> 10000 | E16: =IFERROR((C16-D16)/C16,"-") -> - | F16: =IFERROR(B16/E16,"-") -> -
A17: =EDATE(TODAY(),-1) -> 46234 | B17: =Assumptions!$B$4+Assumptions!$B$5+Assumptions!$B$6 -> 10000 | E17: =IFERROR((C17-D17)/C17,"-") -> - | F17: =IFERROR(B17/E17,"-") -> -
A18: =EDATE(TODAY(),-0) -> 46265 | B18: =Assumptions!$B$4+Assumptions!$B$5+Assumptions!$B$6 -> 10000 | C18: 12000 | D18: 1400 | E18: =IFERROR((C18-D18)/C18,"-") -> 0.88333333 | F18: =IFERROR(B18/E18,"-") -> 11320.755
A21: Read it:
A22: Revenue ≥ Breakeven but reserves still eroding → Contribution Margin too thin → pricing problem.
A23: Revenue consistently below Breakeven → not enough deals/cohorts closing → volume problem.
A24: Both below target → fix volume first; a price increase on too little pipeline won't save you.

Sheet 7. Project Profitability
A1: Monthly Board Slide 3 — Project Profitability (TEHR)
A2: Formula B: True Effective Hourly Rate = Fee Collected ÷ (Delivery + Admin + Sales + Rework Hours)
A4: Project | B4: Fee Collected | C4: Delivery Hrs | D4: Admin Hrs | E4: Sales/Proposal Hrs | F4: Rework Hrs | G4: Total Hours | H4: TEHR | I4: Flag
A5: Acme Corp — Strategy Advisory | B5: 60000 | C5: 165 | D5: 22 | E5: 8 | F5: 6 | G5: =IFERROR(SUM(C5:F5),"-") -> 201 | H5: =IFERROR(B5/G5,"-") -> 298.50746 | I5: =IF(A5="","",IF(H5="-","-",IF(H5<Assumptions!$B$15,"PRICING PROBLEM","OK"))) -> OK
G6: =IFERROR(SUM(C6:F6),"-") -> 0 | H6: =IFERROR(B6/G6,"-") -> - | I6: =IF(A6="","",IF(H6="-","-",IF(H6<Assumptions!$B$15,"PRICING PROBLEM","OK")))
G7: =IFERROR(SUM(C7:F7),"-") -> 0 | H7: =IFERROR(B7/G7,"-") -> - | I7: =IF(A7="","",IF(H7="-","-",IF(H7<Assumptions!$B$15,"PRICING PROBLEM","OK")))
G8: =IFERROR(SUM(C8:F8),"-") -> 0 | H8: =IFERROR(B8/G8,"-") -> - | I8: =IF(A8="","",IF(H8="-","-",IF(H8<Assumptions!$B$15,"PRICING PROBLEM","OK")))
G9: =IFERROR(SUM(C9:F9),"-") -> 0 | H9: =IFERROR(B9/G9,"-") -> - | I9: =IF(A9="","",IF(H9="-","-",IF(H9<Assumptions!$B$15,"PRICING PROBLEM","OK")))
G10: =IFERROR(SUM(C10:F10),"-") -> 0 | H10: =IFERROR(B10/G10,"-") -> - | I10: =IF(A10="","",IF(H10="-","-",IF(H10<Assumptions!$B$15,"PRICING PROBLEM","OK")))
G11: =IFERROR(SUM(C11:F11),"-") -> 0 | H11: =IFERROR(B11/G11,"-") -> - | I11: =IF(A11="","",IF(H11="-","-",IF(H11<Assumptions!$B$15,"PRICING PROBLEM","OK")))
G12: =IFERROR(SUM(C12:F12),"-") -> 0 | H12: =IFERROR(B12/G12,"-") -> - | I12: =IF(A12="","",IF(H12="-","-",IF(H12<Assumptions!$B$15,"PRICING PROBLEM","OK")))
G13: =IFERROR(SUM(C13:F13),"-") -> 0 | H13: =IFERROR(B13/G13,"-") -> - | I13: =IF(A13="","",IF(H13="-","-",IF(H13<Assumptions!$B$15,"PRICING PROBLEM","OK")))
G14: =IFERROR(SUM(C14:F14),"-") -> 0 | H14: =IFERROR(B14/G14,"-") -> - | I14: =IF(A14="","",IF(H14="-","-",IF(H14<Assumptions!$B$15,"PRICING PROBLEM","OK")))
G15: =IFERROR(SUM(C15:F15),"-") -> 0 | H15: =IFERROR(B15/G15,"-") -> - | I15: =IF(A15="","",IF(H15="-","-",IF(H15<Assumptions!$B$15,"PRICING PROBLEM","OK")))
G16: =IFERROR(SUM(C16:F16),"-") -> 0 | H16: =IFERROR(B16/G16,"-") -> - | I16: =IF(A16="","",IF(H16="-","-",IF(H16<Assumptions!$B$15,"PRICING PROBLEM","OK")))

Sheet 8. 13-Week Pipeline
A1: 13-Week Forecast — Pipeline & Renewals
A2: List every open advisory deal and every retainer renewal falling inside the next 13 weeks.
A4: Stage Probability Table
A5: Stage | B5: Probability
A6: Discovery call held | B6: 0.1
A7: Proposal sent | B7: 0.5
A8: Verbal commitment | B8: 0.9
A9: Contract signed | B9: 1
A12: Advisory Pipeline (weighted by stage)
A13: Deal Name | B13: Deal Value | C13: Stage | D13: Probability | E13: Weighted Value | F13: Expected Cash Week (1-13)
A14: New Prospect — Training Cohort Q1 | B14: 18000 | C14: Proposal sent | D14: =IFERROR(INDEX($B$6:$B$9,MATCH(C14,$A$6:$A$9,0)),"-") -> 0.5 | E14: =IFERROR(B14*D14,"-") -> 9000 | F14: 4
D15: =IFERROR(INDEX($B$6:$B$9,MATCH(C15,$A$6:$A$9,0)),"-") -> - | E15: =IFERROR(B15*D15,"-") -> -
D16: =IFERROR(INDEX($B$6:$B$9,MATCH(C16,$A$6:$A$9,0)),"-") -> - | E16: =IFERROR(B16*D16,"-") -> -
D17: =IFERROR(INDEX($B$6:$B$9,MATCH(C17,$A$6:$A$9,0)),"-") -> - | E17: =IFERROR(B17*D17,"-") -> -
D18: =IFERROR(INDEX($B$6:$B$9,MATCH(C18,$A$6:$A$9,0)),"-") -> - | E18: =IFERROR(B18*D18,"-") -> -
D19: =IFERROR(INDEX($B$6:$B$9,MATCH(C19,$A$6:$A$9,0)),"-") -> - | E19: =IFERROR(B19*D19,"-") -> -
D20: =IFERROR(INDEX($B$6:$B$9,MATCH(C20,$A$6:$A$9,0)),"-") -> - | E20: =IFERROR(B20*D20,"-") -> -
D21: =IFERROR(INDEX($B$6:$B$9,MATCH(C21,$A$6:$A$9,0)),"-") -> - | E21: =IFERROR(B21*D21,"-") -> -
D22: =IFERROR(INDEX($B$6:$B$9,MATCH(C22,$A$6:$A$9,0)),"-") -> - | E22: =IFERROR(B22*D22,"-") -> -
D23: =IFERROR(INDEX($B$6:$B$9,MATCH(C23,$A$6:$A$9,0)),"-") -> - | E23: =IFERROR(B23*D23,"-") -> -
D24: =IFERROR(INDEX($B$6:$B$9,MATCH(C24,$A$6:$A$9,0)),"-") -> - | E24: =IFERROR(B24*D24,"-") -> -
D25: =IFERROR(INDEX($B$6:$B$9,MATCH(C25,$A$6:$A$9,0)),"-") -> - | E25: =IFERROR(B25*D25,"-") -> -
A28: Retainer Renewals (pulled from sheet 5, weighted by renewal probability)
A29: Retainer | B29: Monthly Value | C29: Renewal Probability | D29: Weighted Value | F29: Expected Cash Week (1-13)
A30: ='5. Weekly - Retainer Risk'!A5 -> Beta Industries — Monthly Advisory | B30: =IF('5. Weekly - Retainer Risk'!A5="","",'5. Weekly - Retainer Risk'!B5) -> 4000 | C30: =IF('5. Weekly - Retainer Risk'!A5="","",'5. Weekly - Retainer Risk'!H5) -> 0.3 | D30: =IFERROR(B30*C30,"-") -> 1200 | F30: 4
A31: ='5. Weekly - Retainer Risk'!A6 -> 0 | B31: =IF('5. Weekly - Retainer Risk'!A6="","",'5. Weekly - Retainer Risk'!B6) | C31: =IF('5. Weekly - Retainer Risk'!A6="","",'5. Weekly - Retainer Risk'!H6) | D31: =IFERROR(B31*C31,"-") -> -
A32: ='5. Weekly - Retainer Risk'!A7 -> 0 | B32: =IF('5. Weekly - Retainer Risk'!A7="","",'5. Weekly - Retainer Risk'!B7) | C32: =IF('5. Weekly - Retainer Risk'!A7="","",'5. Weekly - Retainer Risk'!H7) | D32: =IFERROR(B32*C32,"-") -> -
A33: ='5. Weekly - Retainer Risk'!A8 -> 0 | B33: =IF('5. Weekly - Retainer Risk'!A8="","",'5. Weekly - Retainer Risk'!B8) | C33: =IF('5. Weekly - Retainer Risk'!A8="","",'5. Weekly - Retainer Risk'!H8) | D33: =IFERROR(B33*C33,"-") -> -
A34: ='5. Weekly - Retainer Risk'!A9 -> 0 | B34: =IF('5. Weekly - Retainer Risk'!A9="","",'5. Weekly - Retainer Risk'!B9) | C34: =IF('5. Weekly - Retainer Risk'!A9="","",'5. Weekly - Retainer Risk'!H9) | D34: =IFERROR(B34*C34,"-") -> -
A35: ='5. Weekly - Retainer Risk'!A10 -> 0 | B35: =IF('5. Weekly - Retainer Risk'!A10="","",'5. Weekly - Retainer Risk'!B10) | C35: =IF('5. Weekly - Retainer Risk'!A10="","",'5. Weekly - Retainer Risk'!H10) | D35: =IFERROR(B35*C35,"-") -> -
A36: ='5. Weekly - Retainer Risk'!A11 -> 0 | B36: =IF('5. Weekly - Retainer Risk'!A11="","",'5. Weekly - Retainer Risk'!B11) | C36: =IF('5. Weekly - Retainer Risk'!A11="","",'5. Weekly - Retainer Risk'!H11) | D36: =IFERROR(B36*C36,"-") -> -
A37: ='5. Weekly - Retainer Risk'!A12 -> 0 | B37: =IF('5. Weekly - Retainer Risk'!A12="","",'5. Weekly - Retainer Risk'!B12) | C37: =IF('5. Weekly - Retainer Risk'!A12="","",'5. Weekly - Retainer Risk'!H12) | D37: =IFERROR(B37*C37,"-") -> -
A38: ='5. Weekly - Retainer Risk'!A13 -> 0 | B38: =IF('5. Weekly - Retainer Risk'!A13="","",'5. Weekly - Retainer Risk'!B13) | C38: =IF('5. Weekly - Retainer Risk'!A13="","",'5. Weekly - Retainer Risk'!H13) | D38: =IFERROR(B38*C38,"-") -> -
A39: ='5. Weekly - Retainer Risk'!A14 -> 0 | B39: =IF('5. Weekly - Retainer Risk'!A14="","",'5. Weekly - Retainer Risk'!B14) | C39: =IF('5. Weekly - Retainer Risk'!A14="","",'5. Weekly - Retainer Risk'!H14) | D39: =IFERROR(B39*C39,"-") -> -

Sheet 9. 13-Week Forecast
A1: Rolling 13-Week Cash Forecast
A2: Rebuild every Friday. Floor = confirmed only. Base = weighted. Best = pipeline at 100%.
A4: Starting Cash Balance
A5: Starting Cash Balance ($) | B5: 42000 | D5: 4-Week Cash Floor Alert Threshold (4x Fixed Costs) | F5: =Assumptions!$B$4*4+Assumptions!$B$5*4+Assumptions!$B$6*4 -> 40000
A7: Week | B7: Week Start | C7: Confirmed Inflow | D7: Confirmed Outflow | E7: Pipeline Weighted Inflow | F7: Retainer Weighted Inflow | G7: Best-Case Inflow (100%) | H7: Floor Cash Balance | I7: Base (Weighted) Cash Balance | J7: Best-Case Cash Balance
A8: 1 | B8: =TODAY() -> 46265 | D8: =(Assumptions!$B$4+Assumptions!$B$5+Assumptions!$B$6)/4.33 -> 2309.4688 | E8: =SUMIFS('8. 13-Week Pipeline'!$E$14:$E$25,'8. 13-Week Pipeline'!$F$14:$F$25,A8) -> 0 | F8: =SUMIFS('8. 13-Week Pipeline'!$D$30:$D$39,'8. 13-Week Pipeline'!$F$30:$F$39,A8) -> 0 | G8: =SUMIFS('8. 13-Week Pipeline'!$B$14:$B$25,'8. 13-Week Pipeline'!$F$14:$F$25,A8)+SUMIFS('8. 13-Week Pipeline'!$B$30:$B$39,'8. 13-Week Pipeline'!$F$30:$F$39,A8) -> 0 | H8: =$B$5+C8-D8 -> 39690.531 | I8: =$B$5+C8-D8+E8+F8 -> 39690.531 | J8: =$B$5+C8-D8+G8 -> 39690.531
A9: 2 | B9: =B8+7 -> 46272 | D9: =(Assumptions!$B$4+Assumptions!$B$5+Assumptions!$B$6)/4.33 -> 2309.4688 | E9: =SUMIFS('8. 13-Week Pipeline'!$E$14:$E$25,'8. 13-Week Pipeline'!$F$14:$F$25,A9) -> 0 | F9: =SUMIFS('8. 13-Week Pipeline'!$D$30:$D$39,'8. 13-Week Pipeline'!$F$30:$F$39,A9) -> 0 | G9: =SUMIFS('8. 13-Week Pipeline'!$B$14:$B$25,'8. 13-Week Pipeline'!$F$14:$F$25,A9)+SUMIFS('8. 13-Week Pipeline'!$B$30:$B$39,'8. 13-Week Pipeline'!$F$30:$F$39,A9) -> 0 | H9: =H8+C9-D9 -> 37381.062 | I9: =I8+C9-D9+E9+F9 -> 37381.062 | J9: =J8+C9-D9+G9 -> 37381.062
A10: 3 | B10: =B9+7 -> 46279 | D10: =(Assumptions!$B$4+Assumptions!$B$5+Assumptions!$B$6)/4.33 -> 2309.4688 | E10: =SUMIFS('8. 13-Week Pipeline'!$E$14:$E$25,'8. 13-Week Pipeline'!$F$14:$F$25,A10) -> 0 | F10: =SUMIFS('8. 13-Week Pipeline'!$D$30:$D$39,'8. 13-Week Pipeline'!$F$30:$F$39,A10) -> 0 | G10: =SUMIFS('8. 13-Week Pipeline'!$B$14:$B$25,'8. 13-Week Pipeline'!$F$14:$F$25,A10)+SUMIFS('8. 13-Week Pipeline'!$B$30:$B$39,'8. 13-Week Pipeline'!$F$30:$F$39,A10) -> 0 | H10: =H9+C10-D10 -> 35071.594 | I10: =I9+C10-D10+E10+F10 -> 35071.594 | J10: =J9+C10-D10+G10 -> 35071.594
A11: 4 | B11: =B10+7 -> 46286 | D11: =(Assumptions!$B$4+Assumptions!$B$5+Assumptions!$B$6)/4.33 -> 2309.4688 | E11: =SUMIFS('8. 13-Week Pipeline'!$E$14:$E$25,'8. 13-Week Pipeline'!$F$14:$F$25,A11) -> 9000 | F11: =SUMIFS('8. 13-Week Pipeline'!$D$30:$D$39,'8. 13-Week Pipeline'!$F$30:$F$39,A11) -> 1200 | G11: =SUMIFS('8. 13-Week Pipeline'!$B$14:$B$25,'8. 13-Week Pipeline'!$F$14:$F$25,A11)+SUMIFS('8. 13-Week Pipeline'!$B$30:$B$39,'8. 13-Week Pipeline'!$F$30:$F$39,A11) -> 22000 | H11: =H10+C11-D11 -> 32762.125 | I11: =I10+C11-D11+E11+F11 -> 42962.125 | J11: =J10+C11-D11+G11 -> 54762.125
A12: 5 | B12: =B11+7 -> 46293 | D12: =(Assumptions!$B$4+Assumptions!$B$5+Assumptions!$B$6)/4.33 -> 2309.4688 | E12: =SUMIFS('8. 13-Week Pipeline'!$E$14:$E$25,'8. 13-Week Pipeline'!$F$14:$F$25,A12) -> 0 | F12: =SUMIFS('8. 13-Week Pipeline'!$D$30:$D$39,'8. 13-Week Pipeline'!$F$30:$F$39,A12) -> 0 | G12: =SUMIFS('8. 13-Week Pipeline'!$B$14:$B$25,'8. 13-Week Pipeline'!$F$14:$F$25,A12)+SUMIFS('8. 13-Week Pipeline'!$B$30:$B$39,'8. 13-Week Pipeline'!$F$30:$F$39,A12) -> 0 | H12: =H11+C12-D12 -> 30452.656 | I12: =I11+C12-D12+E12+F12 -> 40652.656 | J12: =J11+C12-D12+G12 -> 52452.656
A13: 6 | B13: =B12+7 -> 46300 | D13: =(Assumptions!$B$4+Assumptions!$B$5+Assumptions!$B$6)/4.33 -> 2309.4688 | E13: =SUMIFS('8. 13-Week Pipeline'!$E$14:$E$25,'8. 13-Week Pipeline'!$F$14:$F$25,A13) -> 0 | F13: =SUMIFS('8. 13-Week Pipeline'!$D$30:$D$39,'8. 13-Week Pipeline'!$F$30:$F$39,A13) -> 0 | G13: =SUMIFS('8. 13-Week Pipeline'!$B$14:$B$25,'8. 13-Week Pipeline'!$F$14:$F$25,A13)+SUMIFS('8. 13-Week Pipeline'!$B$30:$B$39,'8. 13-Week Pipeline'!$F$30:$F$39,A13) -> 0 | H13: =H12+C13-D13 -> 28143.187 | I13: =I12+C13-D13+E13+F13 -> 38343.187 | J13: =J12+C13-D13+G13 -> 50143.187
A14: 7 | B14: =B13+7 -> 46307 | D14: =(Assumptions!$B$4+Assumptions!$B$5+Assumptions!$B$6)/4.33 -> 2309.4688 | E14: =SUMIFS('8. 13-Week Pipeline'!$E$14:$E$25,'8. 13-Week Pipeline'!$F$14:$F$25,A14) -> 0 | F14: =SUMIFS('8. 13-Week Pipeline'!$D$30:$D$39,'8. 13-Week Pipeline'!$F$30:$F$39,A14) -> 0 | G14: =SUMIFS('8. 13-Week Pipeline'!$B$14:$B$25,'8. 13-Week Pipeline'!$F$14:$F$25,A14)+SUMIFS('8. 13-Week Pipeline'!$B$30:$B$39,'8. 13-Week Pipeline'!$F$30:$F$39,A14) -> 0 | H14: =H13+C14-D14 -> 25833.718 | I14: =I13+C14-D14+E14+F14 -> 36033.718 | J14: =J13+C14-D14+G14 -> 47833.718
A15: 8 | B15: =B14+7 -> 46314 | D15: =(Assumptions!$B$4+Assumptions!$B$5+Assumptions!$B$6)/4.33 -> 2309.4688 | E15: =SUMIFS('8. 13-Week Pipeline'!$E$14:$E$25,'8. 13-Week Pipeline'!$F$14:$F$25,A15) -> 0 | F15: =SUMIFS('8. 13-Week Pipeline'!$D$30:$D$39,'8. 13-Week Pipeline'!$F$30:$F$39,A15) -> 0 | G15: =SUMIFS('8. 13-Week Pipeline'!$B$14:$B$25,'8. 13-Week Pipeline'!$F$14:$F$25,A15)+SUMIFS('8. 13-Week Pipeline'!$B$30:$B$39,'8. 13-Week Pipeline'!$F$30:$F$39,A15) -> 0 | H15: =H14+C15-D15 -> 23524.249 | I15: =I14+C15-D15+E15+F15 -> 33724.249 | J15: =J14+C15-D15+G15 -> 45524.249
A16: 9 | B16: =B15+7 -> 46321 | D16: =(Assumptions!$B$4+Assumptions!$B$5+Assumptions!$B$6)/4.33 -> 2309.4688 | E16: =SUMIFS('8. 13-Week Pipeline'!$E$14:$E$25,'8. 13-Week Pipeline'!$F$14:$F$25,A16) -> 0 | F16: =SUMIFS('8. 13-Week Pipeline'!$D$30:$D$39,'8. 13-Week Pipeline'!$F$30:$F$39,A16) -> 0 | G16: =SUMIFS('8. 13-Week Pipeline'!$B$14:$B$25,'8. 13-Week Pipeline'!$F$14:$F$25,A16)+SUMIFS('8. 13-Week Pipeline'!$B$30:$B$39,'8. 13-Week Pipeline'!$F$30:$F$39,A16) -> 0 | H16: =H15+C16-D16 -> 21214.781 | I16: =I15+C16-D16+E16+F16 -> 31414.781 | J16: =J15+C16-D16+G16 -> 43214.781
A17: 10 | B17: =B16+7 -> 46328 | D17: =(Assumptions!$B$4+Assumptions!$B$5+Assumptions!$B$6)/4.33 -> 2309.4688 | E17: =SUMIFS('8. 13-Week Pipeline'!$E$14:$E$25,'8. 13-Week Pipeline'!$F$14:$F$25,A17) -> 0 | F17: =SUMIFS('8. 13-Week Pipeline'!$D$30:$D$39,'8. 13-Week Pipeline'!$F$30:$F$39,A17) -> 0 | G17: =SUMIFS('8. 13-Week Pipeline'!$B$14:$B$25,'8. 13-Week Pipeline'!$F$14:$F$25,A17)+SUMIFS('8. 13-Week Pipeline'!$B$30:$B$39,'8. 13-Week Pipeline'!$F$30:$F$39,A17) -> 0 | H17: =H16+C17-D17 -> 18905.312 | I17: =I16+C17-D17+E17+F17 -> 29105.312 | J17: =J16+C17-D17+G17 -> 40905.312
A18: 11 | B18: =B17+7 -> 46335 | D18: =(Assumptions!$B$4+Assumptions!$B$5+Assumptions!$B$6)/4.33 -> 2309.4688 | E18: =SUMIFS('8. 13-Week Pipeline'!$E$14:$E$25,'8. 13-Week Pipeline'!$F$14:$F$25,A18) -> 0 | F18: =SUMIFS('8. 13-Week Pipeline'!$D$30:$D$39,'8. 13-Week Pipeline'!$F$30:$F$39,A18) -> 0 | G18: =SUMIFS('8. 13-Week Pipeline'!$B$14:$B$25,'8. 13-Week Pipeline'!$F$14:$F$25,A18)+SUMIFS('8. 13-Week Pipeline'!$B$30:$B$39,'8. 13-Week Pipeline'!$F$30:$F$39,A18) -> 0 | H18: =H17+C18-D18 -> 16595.843 | I18: =I17+C18-D18+E18+F18 -> 26795.843 | J18: =J17+C18-D18+G18 -> 38595.843
A19: 12 | B19: =B18+7 -> 46342 | D19: =(Assumptions!$B$4+Assumptions!$B$5+Assumptions!$B$6)/4.33 -> 2309.4688 | E19: =SUMIFS('8. 13-Week Pipeline'!$E$14:$E$25,'8. 13-Week Pipeline'!$F$14:$F$25,A19) -> 0 | F19: =SUMIFS('8. 13-Week Pipeline'!$D$30:$D$39,'8. 13-Week Pipeline'!$F$30:$F$39,A19) -> 0 | G19: =SUMIFS('8. 13-Week Pipeline'!$B$14:$B$25,'8. 13-Week Pipeline'!$F$14:$F$25,A19)+SUMIFS('8. 13-Week Pipeline'!$B$30:$B$39,'8. 13-Week Pipeline'!$F$30:$F$39,A19) -> 0 | H19: =H18+C19-D19 -> 14286.374 | I19: =I18+C19-D19+E19+F19 -> 24486.374 | J19: =J18+C19-D19+G19 -> 36286.374
A20: 13 | B20: =B19+7 -> 46349 | D20: =(Assumptions!$B$4+Assumptions!$B$5+Assumptions!$B$6)/4.33 -> 2309.4688 | E20: =SUMIFS('8. 13-Week Pipeline'!$E$14:$E$25,'8. 13-Week Pipeline'!$F$14:$F$25,A20) -> 0 | F20: =SUMIFS('8. 13-Week Pipeline'!$D$30:$D$39,'8. 13-Week Pipeline'!$F$30:$F$39,A20) -> 0 | G20: =SUMIFS('8. 13-Week Pipeline'!$B$14:$B$25,'8. 13-Week Pipeline'!$F$14:$F$25,A20)+SUMIFS('8. 13-Week Pipeline'!$B$30:$B$39,'8. 13-Week Pipeline'!$F$30:$F$39,A20) -> 0 | H20: =H19+C20-D20 -> 11976.905 | I20: =I19+C20-D20+E20+F20 -> 22176.905 | J20: =J19+C20-D20+G20 -> 33976.905
A23: Trigger: | B23: If Base (Weighted) Cash Balance dips below the 4-Week Alert Threshold at any point above, act now: push AR collection, intensify pipeline activity, or delay a discretionary expense.
